Workbook

Sheet Dashboard
B1: E-Commerce Sales Dashboard
B2: Orders from Mar 2023 to Feb 2024 · all figures are live formulas over the Customers, Products, Orders and OrderDetails sheets
B4: Total Revenue | C4: Total Orders | D4: Avg Order Value | E4: Total Customers | F4: Buying Customers | G4: Repeat Rate
B5: =SUM(Orders!$D$2:$D$201) -> 19783000 | C5: =COUNT(Orders!$A$2:$A$201) -> 200 | D5: =B5/C5 -> 98915 | E5: =COUNTA(Customers!$A$2:$A$101) -> 100 | F5: =COUNTIF(Customers!$D$2:$D$101,">0") -> 84 | G5: =COUNTIF(Customers!$D$2:$D$101,">1")/F5 -> 0.69047619
B8: Monthly sales trend
B9: Month | C9: Month key | D9: Orders | E9: Sales | F9: MoM change
B10: 2023-03 | C10: 202303 | D10: =COUNTIF(Orders!$F$2:$F$201,C10) -> 13 | E10: =SUMIF(Orders!$F$2:$F$201,C10,Orders!$D$2:$D$201) -> 789000
B11: 2023-04 | C11: 202304 | D11: =COUNTIF(Orders!$F$2:$F$201,C11) -> 21 | E11: =SUMIF(Orders!$F$2:$F$201,C11,Orders!$D$2:$D$201) -> 1704000 | F11: =(E11-E10)/E10 -> 1.1596958
B12: 2023-05 | C12: 202305 | D12: =COUNTIF(Orders!$F$2:$F$201,C12) -> 18 | E12: =SUMIF(Orders!$F$2:$F$201,C12,Orders!$D$2:$D$201) -> 1582000 | F12: =(E12-E11)/E11 -> -0.071596244
B13: 2023-06 | C13: 202306 | D13: =COUNTIF(Orders!$F$2:$F$201,C13) -> 10 | E13: =SUMIF(Orders!$F$2:$F$201,C13,Orders!$D$2:$D$201) -> 1040000 | F13: =(E13-E12)/E12 -> -0.3426043
B14: 2023-07 | C14: 202307 | D14: =COUNTIF(Orders!$F$2:$F$201,C14) -> 26 | E14: =SUMIF(Orders!$F$2:$F$201,C14,Orders!$D$2:$D$201) -> 2568000 | F14: =(E14-E13)/E13 -> 1.4692308
B15: 2023-08 | C15: 202308 | D15: =COUNTIF(Orders!$F$2:$F$201,C15) -> 16 | E15: =SUMIF(Orders!$F$2:$F$201,C15,Orders!$D$2:$D$201) -> 1800000 | F15: =(E15-E14)/E14 -> -0.29906542
B16: 2023-09 | C16: 202309 | D16: =COUNTIF(Orders!$F$2:$F$201,C16) -> 24 | E16: =SUMIF(Orders!$F$2:$F$201,C16,Orders!$D$2:$D$201) -> 2927000 | F16: =(E16-E15)/E15 -> 0.62611111
B17: 2023-10 | C17: 202310 | D17: =COUNTIF(Orders!$F$2:$F$201,C17) -> 18 | E17: =SUMIF(Orders!$F$2:$F$201,C17,Orders!$D$2:$D$201) -> 1497000 | F17: =(E17-E16)/E16 -> -0.48855483
B18: 2023-11 | C18: 202311 | D18: =COUNTIF(Orders!$F$2:$F$201,C18) -> 12 | E18: =SUMIF(Orders!$F$2:$F$201,C18,Orders!$D$2:$D$201) -> 1151000 | F18: =(E18-E17)/E17 -> -0.23112892
B19: 2023-12 | C19: 202312 | D19: =COUNTIF(Orders!$F$2:$F$201,C19) -> 21 | E19: =SUMIF(Orders!$F$2:$F$201,C19,Orders!$D$2:$D$201) -> 2774000 | F19: =(E19-E18)/E18 -> 1.4100782
B20: 2024-01 | C20: 202401 | D20: =COUNTIF(Orders!$F$2:$F$201,C20) -> 12 | E20: =SUMIF(Orders!$F$2:$F$201,C20,Orders!$D$2:$D$201) -> 1555000 | F20: =(E20-E19)/E19 -> -0.43943764
B21: 2024-02 | C21: 202402 | D21: =COUNTIF(Orders!$F$2:$F$201,C21) -> 9 | E21: =SUMIF(Orders!$F$2:$F$201,C21,Orders!$D$2:$D$201) -> 396000 | F21: =(E21-E20)/E20 -> -0.74533762
B22: Total | D22: =SUM(D10:D21) -> 200 | E22: =SUM(E10:E21) -> 19783000
B25: Revenue by category
B26: Category | C26: Units sold | D26: Revenue | E26: Share
B27: Electronics | C27: =SUMIF(OrderDetails!$G$2:$G$520,B27,OrderDetails!$C$2:$C$520) -> 633 | D27: =SUMIF(OrderDetails!$G$2:$G$520,B27,OrderDetails!$E$2:$E$520) -> 12758000 | E27: =D27/SUM($D$27:$D$29) -> 0.64489713
B28: Photography | C28: =SUMIF(OrderDetails!$G$2:$G$520,B28,OrderDetails!$C$2:$C$520) -> 151 | D28: =SUMIF(OrderDetails!$G$2:$G$520,B28,OrderDetails!$E$2:$E$520) -> 6040000 | E28: =D28/SUM($D$27:$D$29) -> 0.30531264
B29: Wearable Tech | C29: =SUMIF(OrderDetails!$G$2:$G$520,B29,OrderDetails!$C$2:$C$520) -> 249 | D29: =SUMIF(OrderDetails!$G$2:$G$520,B29,OrderDetails!$E$2:$E$520) -> 985000 | E29: =D29/SUM($D$27:$D$29) -> 0.049790224
B42: Revenue by product
B43: Product | C43: Units sold | D43: Revenue | E43: Order lines
B44: Laptop 15" Pro | C44: =SUMIF(OrderDetails!$F$2:$F$520,B44,OrderDetails!$C$2:$C$520) -> 126 | D44: =SUMIF(OrderDetails!$F$2:$F$520,B44,OrderDetails!$E$2:$E$520) -> 7560000 | E44: =COUNTIF(OrderDetails!$F$2:$F$520,B44) -> 67
B45: Digital SLR Camera | C45: =SUMIF(OrderDetails!$F$2:$F$520,B45,OrderDetails!$C$2:$C$520) -> 151 | D45: =SUMIF(OrderDetails!$F$2:$F$520,B45,OrderDetails!$E$2:$E$520) -> 6040000 | E45: =COUNTIF(OrderDetails!$F$2:$F$520,B45) -> 78
B46: Smartphone 6" | C46: =SUMIF(OrderDetails!$F$2:$F$520,B46,OrderDetails!$C$2:$C$520) -> 108 | D46: =SUMIF(OrderDetails!$F$2:$F$520,B46,OrderDetails!$E$2:$E$520) -> 1620000 | E46: =COUNTIF(OrderDetails!$F$2:$F$520,B46) -> 54
B47: E-Book Reader | C47: =SUMIF(OrderDetails!$F$2:$F$520,B47,OrderDetails!$C$2:$C$520) -> 130 | D47: =SUMIF(OrderDetails!$F$2:$F$520,B47,OrderDetails!$E$2:$E$520) -> 1560000 | E47: =COUNTIF(OrderDetails!$F$2:$F$520,B47) -> 68
B48: Bluetooth Headphones | C48: =SUMIF(OrderDetails!$F$2:$F$520,B48,OrderDetails!$C$2:$C$520) -> 135 | D48: =SUMIF(OrderDetails!$F$2:$F$520,B48,OrderDetails!$E$2:$E$520) -> 1080000 | E48: =COUNTIF(OrderDetails!$F$2:$F$520,B48) -> 68
B49: Portable Bluetooth Speaker | C49: =SUMIF(OrderDetails!$F$2:$F$520,B49,OrderDetails!$C$2:$C$520) -> 134 | D49: =SUMIF(OrderDetails!$F$2:$F$520,B49,OrderDetails!$E$2:$E$520) -> 938000 | E49: =COUNTIF(OrderDetails!$F$2:$F$520,B49) -> 59
B50: Smartwatch Fitness Tracker | C50: =SUMIF(OrderDetails!$F$2:$F$520,B50,OrderDetails!$C$2:$C$520) -> 119 | D50: =SUMIF(OrderDetails!$F$2:$F$520,B50,OrderDetails!$E$2:$E$520) -> 595000 | E50: =COUNTIF(OrderDetails!$F$2:$F$520,B50) -> 60
B51: Wireless Earbuds | C51: =SUMIF(OrderDetails!$F$2:$F$520,B51,OrderDetails!$C$2:$C$520) -> 130 | D51: =SUMIF(OrderDetails!$F$2:$F$520,B51,OrderDetails!$E$2:$E$520) -> 390000 | E51: =COUNTIF(OrderDetails!$F$2:$F$520,B51) -> 65
B59: Revenue by city
B60: City | C60: Customers | D60: Orders | E60: Revenue
B61: Chennai | C61: =COUNTIF(Customers!$C$2:$C$101,B61) -> 15 | D61: =COUNTIF(Orders!$E$2:$E$201,B61) -> 34 | E61: =SUMIF(Orders!$E$2:$E$201,B61,Orders!$D$2:$D$201) -> 3890000
B62: Lucknow | C62: =COUNTIF(Customers!$C$2:$C$101,B62) -> 9 | D62: =COUNTIF(Orders!$E$2:$E$201,B62) -> 24 | E62: =SUMIF(Orders!$E$2:$E$201,B62,Orders!$D$2:$D$201) -> 2206000
B63: Jaipur | C63: =COUNTIF(Customers!$C$2:$C$101,B63) -> 11 | D63: =COUNTIF(Orders!$E$2:$E$201,B63) -> 22 | E63: =SUMIF(Orders!$E$2:$E$201,B63,Orders!$D$2:$D$201) -> 2102000
B64: Delhi | C64: =COUNTIF(Customers!$C$2:$C$101,B64) -> 16 | D64: =COUNTIF(Orders!$E$2:$E$201,B64) -> 28 | E64: =SUMIF(Orders!$E$2:$E$201,B64,Orders!$D$2:$D$201) -> 2066000
...

Sheet Customers
A1: customer_id | B1: name | C1: location | D1: total_orders | E1: total_spent | F1: segment
A2: 1 | B2: Ivana Chander | C2: Delhi | D2: =COUNTIF(Orders!$C$2:$C$201,A2) -> 1 | E2: =SUMIF(Orders!$C$2:$C$201,A2,Orders!$D$2:$D$201) -> 61000 | F2: =IF(D2=0,"Never ordered",IF(D2=1,"One-time buyer",IF(D2<=4,"Occasional shopper","Regular customer"))) -> One-time buyer
A3: 2 | B3: Charvi Kibe | C3: Chennai | D3: =COUNTIF(Orders!$C$2:$C$201,A3) -> 2 | E3: =SUMIF(Orders!$C$2:$C$201,A3,Orders!$D$2:$D$201) -> 219000 | F3: =IF(D3=0,"Never ordered",IF(D3=1,"One-time buyer",IF(D3<=4,"Occasional shopper","Regular customer"))) -> Occasional shopper
A4: 3 | B4: Divij Chaudry | C4: Chennai | D4: =COUNTIF(Orders!$C$2:$C$201,A4) -> 0 | E4: =SUMIF(Orders!$C$2:$C$201,A4,Orders!$D$2:$D$201) -> 0 | F4: =IF(D4=0,"Never ordered",IF(D4=1,"One-time buyer",IF(D4<=4,"Occasional shopper","Regular customer"))) -> Never ordered
A5: 4 | B5: Charvi Balay | C5: Pune | D5: =COUNTIF(Orders!$C$2:$C$201,A5) -> 3 | E5: =SUMIF(Orders!$C$2:$C$201,A5,Orders!$D$2:$D$201) -> 444000 | F5: =IF(D5=0,"Never ordered",IF(D5=1,"One-time buyer",IF(D5<=4,"Occasional shopper","Regular customer"))) -> Occasional shopper
A6: 5 | B6: Diya Arya | C6: Pune | D6: =COUNTIF(Orders!$C$2:$C$201,A6) -> 2 | E6: =SUMIF(Orders!$C$2:$C$201,A6,Orders!$D$2:$D$201) -> 75000 | F6: =IF(D6=0,"Never ordered",IF(D6=1,"One-time buyer",IF(D6<=4,"Occasional shopper","Regular customer"))) -> Occasional shopper
A7: 6 | B7: Dhruv Cherian | C7: Chennai | D7: =COUNTIF(Orders!$C$2:$C$201,A7) -> 0 | E7: =SUMIF(Orders!$C$2:$C$201,A7,Orders!$D$2:$D$201) -> 0 | F7: =IF(D7=0,"Never ordered",IF(D7=1,"One-time buyer",IF(D7<=4,"Occasional shopper","Regular customer"))) -> Never ordered
A8: 7 | B8: Myra Dubey | C8: Chennai | D8: =COUNTIF(Orders!$C$2:$C$201,A8) -> 2 | E8: =SUMIF(Orders!$C$2:$C$201,A8,Orders!$D$2:$D$201) -> 20000 | F8: =IF(D8=0,"Never ordered",IF(D8=1,"One-time buyer",IF(D8<=4,"Occasional shopper","Regular customer"))) -> Occasional shopper
A9: 8 | B9: Advika Wable | C9: Delhi | D9: =COUNTIF(Orders!$C$2:$C$201,A9) -> 0 | E9: =SUMIF(Orders!$C$2:$C$201,A9,Orders!$D$2:$D$201) -> 0 | F9: =IF(D9=0,"Never ordered",IF(D9=1,"One-time buyer",IF(D9<=4,"Occasional shopper","Regular customer"))) -> Never ordered
A10: 9 | B10: Aarna Samra | C10: Hyderabad | D10: =COUNTIF(Orders!$C$2:$C$201,A10) -> 1 | E10: =SUMIF(Orders!$C$2:$C$201,A10,Orders!$D$2:$D$201) -> 12000 | F10: =IF(D10=0,"Never ordered",IF(D10=1,"One-time buyer",IF(D10<=4,"Occasional shopper","Regular customer"))) -> One-time buyer
A11: 10 | B11: Ahana Ray | C11: Ahmedabad | D11: =COUNTIF(Orders!$C$2:$C$201,A11) -> 3 | E11: =SUMIF(Orders!$C$2:$C$201,A11,Orders!$D$2:$D$201) -> 172000 | F11: =IF(D11=0,"Never ordered",IF(D11=1,"One-time buyer",IF(D11<=4,"Occasional shopper","Regular customer"))) -> Occasional shopper
A12: 11 | B12: Tanya Baria | C12: Lucknow | D12: =COUNTIF(Orders!$C$2:$C$201,A12) -> 5 | E12: =SUMIF(Orders!$C$2:$C$201,A12,Orders!$D$2:$D$201) -> 242000 | F12: =IF(D12=0,"Never ordered",IF(D12=1,"One-time buyer",IF(D12<=4,"Occasional shopper","Regular customer"))) -> Regular customer
A13: 12 | B13: Kismat Sangha | C13: Kolkata | D13: =COUNTIF(Orders!$C$2:$C$201,A13) -> 1 | E13: =SUMIF(Orders!$C$2:$C$201,A13,Orders!$D$2:$D$201) -> 185000 | F13: =IF(D13=0,"Never ordered",IF(D13=1,"One-time buyer",IF(D13<=4,"Occasional shopper","Regular customer"))) -> One-time buyer
... A101: 100 | B101: Kimaya Sur | C101: Bangalore | D101: =COUNTIF(Orders!$C$2:$C$201,A101) -> 3 | E101: =SUMIF(Orders!$C$2:$C$201,A101,Orders!$D$2:$D$201) -> 613000 | F101: =IF(D101=0,"Never ordered",IF(D101=1,"One-time buyer",IF(D101<=4,"Occasional shopper","Regular customer"))) -> Occasional shopper

Sheet Products
A1: product_id | B1: name | C1: category | D1: price
A2: 1 | B2: Smartphone 6" | C2: Electronics | D2: 15000
A3: 2 | B3: Laptop 15" Pro | C3: Electronics | D3: 60000
A4: 3 | B4: Bluetooth Headphones | C4: Electronics | D4: 8000
A5: 4 | B5: E-Book Reader | C5: Electronics | D5: 12000
A6: 5 | B6: Smartwatch Fitness Tracker | C6: Wearable Tech | D6: 5000
A7: 6 | B7: Portable Bluetooth Speaker | C7: Electronics | D7: 7000
A8: 7 | B8: Digital SLR Camera | C8: Photography | D8: 40000
A9: 8 | B9: Wireless Earbuds | C9: Wearable Tech | D9: 3000

Sheet Orders
A1: order_id | B1: order_date | C1: customer_id | D1: total_amount | E1: location | F1: month_key
A2: 1 | B2: 45196 | C2: 67 | D2: 45000 | E2: =INDEX(Customers!$C$2:$C$101,MATCH(C2,Customers!$A$2:$A$101,0)) -> Lucknow | F2: =YEAR(B2)*100+MONTH(B2) -> 202309
A3: 2 | B3: 45249 | C3: 98 | D3: 16000 | E3: =INDEX(Customers!$C$2:$C$101,MATCH(C3,Customers!$A$2:$A$101,0)) -> Jaipur | F3: =YEAR(B3)*100+MONTH(B3) -> 202311
A4: 3 | B4: 45280 | C4: 46 | D4: 260000 | E4: =INDEX(Customers!$C$2:$C$101,MATCH(C4,Customers!$A$2:$A$101,0)) -> Delhi | F4: =YEAR(B4)*100+MONTH(B4) -> 202312
A5: 4 | B5: 45045 | C5: 83 | D5: 27000 | E5: =INDEX(Customers!$C$2:$C$101,MATCH(C5,Customers!$A$2:$A$101,0)) -> Mumbai | F5: =YEAR(B5)*100+MONTH(B5) -> 202304
A6: 5 | B6: 45021 | C6: 99 | D6: 221000 | E6: =INDEX(Customers!$C$2:$C$101,MATCH(C6,Customers!$A$2:$A$101,0)) -> Mumbai | F6: =YEAR(B6)*100+MONTH(B6) -> 202304
A7: 6 | B7: 45075 | C7: 59 | D7: 120000 | E7: =INDEX(Customers!$C$2:$C$101,MATCH(C7,Customers!$A$2:$A$101,0)) -> Bangalore | F7: =YEAR(B7)*100+MONTH(B7) -> 202305
A8: 7 | B8: 45042 | C8: 68 | D8: 30000 | E8: =INDEX(Customers!$C$2:$C$101,MATCH(C8,Customers!$A$2:$A$101,0)) -> Chennai | F8: =YEAR(B8)*100+MONTH(B8) -> 202304
A9: 8 | B9: 45144 | C9: 24 | D9: 64000 | E9: =INDEX(Customers!$C$2:$C$101,MATCH(C9,Customers!$A$2:$A$101,0)) -> Mumbai | F9: =YEAR(B9)*100+MONTH(B9) -> 202308
A10: 9 | B10: 45277 | C10: 61 | D10: 250000 | E10: =INDEX(Customers!$C$2:$C$101,MATCH(C10,Customers!$A$2:$A$101,0)) -> Kolkata | F10: =YEAR(B10)*100+MONTH(B10) -> 202312
A11: 10 | B11: 45203 | C11: 38 | D11: 53000 | E11: =INDEX(Customers!$C$2:$C$101,MATCH(C11,Customers!$A$2:$A$101,0)) -> Ahmedabad | F11: =YEAR(B11)*100+MONTH(B11) -> 202310
A12: 11 | B12: 45215 | C12: 95 | D12: 129000 | E12: =INDEX(Customers!$C$2:$C$101,MATCH(C12,Customers!$A$2:$A$101,0)) -> Ahmedabad | F12: =YEAR(B12)*100+MONTH(B12) -> 202310
A13: 12 | B13: 45137 | C13: 78 | D13: 15000 | E13: =INDEX(Customers!$C$2:$C$101,MATCH(C13,Customers!$A$2:$A$101,0)) -> Chennai | F13: =YEAR(B13)*100+MONTH(B13) -> 202307
... A201: 200 | B201: 45092 | C201: 4 | D201: 151000 | E201: =INDEX(Customers!$C$2:$C$101,MATCH(C201,Customers!$A$2:$A$101,0)) -> Pune | F201: =YEAR(B201)*100+MONTH(B201) -> 202306

Sheet OrderDetails
A1: order_id | B1: product_id | C1: quantity | D1: price_per_unit | E1: line_amount | F1: product_name | G1: category | H1: month_key | I1: location
A2: 1 | B2: 1 | C2: 3 | D2: 15000 | E2: =C2*D2 -> 45000 | F2: =INDEX(Products!$B$2:$B$9,MATCH(B2,Products!$A$2:$A$9,0)) -> Smartphone 6" | G2: =INDEX(Products!$C$2:$C$9,MATCH(B2,Products!$A$2:$A$9,0)) -> Electronics | H2: =INDEX(Orders!$F$2:$F$201,MATCH(A2,Orders!$A$2:$A$201,0)) -> 202309 | I2: =INDEX(Orders!$E$2:$E$201,MATCH(A2,Orders!$A$2:$A$201,0)) -> Lucknow
A3: 2 | B3: 3 | C3: 2 | D3: 8000 | E3: =C3*D3 -> 16000 | F3: =INDEX(Products!$B$2:$B$9,MATCH(B3,Products!$A$2:$A$9,0)) -> Bluetooth Headphones | G3: =INDEX(Products!$C$2:$C$9,MATCH(B3,Products!$A$2:$A$9,0)) -> Electronics | H3: =INDEX(Orders!$F$2:$F$201,MATCH(A3,Orders!$A$2:$A$201,0)) -> 202311 | I3: =INDEX(Orders!$E$2:$E$201,MATCH(A3,Orders!$A$2:$A$201,0)) -> Jaipur
A4: 3 | B4: 2 | C4: 1 | D4: 60000 | E4: =C4*D4 -> 60000 | F4: =INDEX(Products!$B$2:$B$9,MATCH(B4,Products!$A$2:$A$9,0)) -> Laptop 15" Pro | G4: =INDEX(Products!$C$2:$C$9,MATCH(B4,Products!$A$2:$A$9,0)) -> Electronics | H4: =INDEX(Orders!$F$2:$F$201,MATCH(A4,Orders!$A$2:$A$201,0)) -> 202312 | I4: =INDEX(Orders!$E$2:$E$201,MATCH(A4,Orders!$A$2:$A$201,0)) -> Delhi
A5: 3 | B5: 7 | C5: 2 | D5: 40000 | E5: =C5*D5 -> 80000 | F5: =INDEX(Products!$B$2:$B$9,MATCH(B5,Products!$A$2:$A$9,0)) -> Digital SLR Camera | G5: =INDEX(Products!$C$2:$C$9,MATCH(B5,Products!$A$2:$A$9,0)) -> Photography | H5: =INDEX(Orders!$F$2:$F$201,MATCH(A5,Orders!$A$2:$A$201,0)) -> 202312 | I5: =INDEX(Orders!$E$2:$E$201,MATCH(A5,Orders!$A$2:$A$201,0)) -> Delhi
A6: 3 | B6: 7 | C6: 3 | D6: 40000 | E6: =C6*D6 -> 120000 | F6: =INDEX(Products!$B$2:$B$9,MATCH(B6,Products!$A$2:$A$9,0)) -> Digital SLR Camera | G6: =INDEX(Products!$C$2:$C$9,MATCH(B6,Products!$A$2:$A$9,0)) -> Photography | H6: =INDEX(Orders!$F$2:$F$201,MATCH(A6,Orders!$A$2:$A$201,0)) -> 202312 | I6: =INDEX(Orders!$E$2:$E$201,MATCH(A6,Orders!$A$2:$A$201,0)) -> Delhi
A7: 4 | B7: 4 | C7: 1 | D7: 12000 | E7: =C7*D7 -> 12000 | F7: =INDEX(Products!$B$2:$B$9,MATCH(B7,Products!$A$2:$A$9,0)) -> E-Book Reader | G7: =INDEX(Products!$C$2:$C$9,MATCH(B7,Products!$A$2:$A$9,0)) -> Electronics | H7: =INDEX(Orders!$F$2:$F$201,MATCH(A7,Orders!$A$2:$A$201,0)) -> 202304 | I7: =INDEX(Orders!$E$2:$E$201,MATCH(A7,Orders!$A$2:$A$201,0)) -> Mumbai
A8: 4 | B8: 1 | C8: 1 | D8: 15000 | E8: =C8*D8 -> 15000 | F8: =INDEX(Products!$B$2:$B$9,MATCH(B8,Products!$A$2:$A$9,0)) -> Smartphone 6" | G8: =INDEX(Products!$C$2:$C$9,MATCH(B8,Products!$A$2:$A$9,0)) -> Electronics | H8: =INDEX(Orders!$F$2:$F$201,MATCH(A8,Orders!$A$2:$A$201,0)) -> 202304 | I8: =INDEX(Orders!$E$2:$E$201,MATCH(A8,Orders!$A$2:$A$201,0)) -> Mumbai
A9: 5 | B9: 5 | C9: 1 | D9: 5000 | E9: =C9*D9 -> 5000 | F9: =INDEX(Products!$B$2:$B$9,MATCH(B9,Products!$A$2:$A$9,0)) -> Smartwatch Fitness Tracker | G9: =INDEX(Products!$C$2:$C$9,MATCH(B9,Products!$A$2:$A$9,0)) -> Wearable Tech | H9: =INDEX(Orders!$F$2:$F$201,MATCH(A9,Orders!$A$2:$A$201,0)) -> 202304 | I9: =INDEX(Orders!$E$2:$E$201,MATCH(A9,Orders!$A$2:$A$201,0)) -> Mumbai
A10: 5 | B10: 4 | C10: 3 | D10: 12000 | E10: =C10*D10 -> 36000 | F10: =INDEX(Products!$B$2:$B$9,MATCH(B10,Products!$A$2:$A$9,0)) -> E-Book Reader | G10: =INDEX(Products!$C$2:$C$9,MATCH(B10,Products!$A$2:$A$9,0)) -> Electronics | H10: =INDEX(Orders!$F$2:$F$201,MATCH(A10,Orders!$A$2:$A$201,0)) -> 202304 | I10: =INDEX(Orders!$E$2:$E$201,MATCH(A10,Orders!$A$2:$A$201,0)) -> Mumbai
A11: 5 | B11: 2 | C11: 3 | D11: 60000 | E11: =C11*D11 -> 180000 | F11: =INDEX(Products!$B$2:$B$9,MATCH(B11,Products!$A$2:$A$9,0)) -> Laptop 15" Pro | G11: =INDEX(Products!$C$2:$C$9,MATCH(B11,Products!$A$2:$A$9,0)) -> Electronics | H11: =INDEX(Orders!$F$2:$F$201,MATCH(A11,Orders!$A$2:$A$201,0)) -> 202304 | I11: =INDEX(Orders!$E$2:$E$201,MATCH(A11,Orders!$A$2:$A$201,0)) -> Mumbai
A12: 6 | B12: 7 | C12: 1 | D12: 40000 | E12: =C12*D12 -> 40000 | F12: =INDEX(Products!$B$2:$B$9,MATCH(B12,Products!$A$2:$A$9,0)) -> Digital SLR Camera | G12: =INDEX(Products!$C$2:$C$9,MATCH(B12,Products!$A$2:$A$9,0)) -> Photography | H12: =INDEX(Orders!$F$2:$F$201,MATCH(A12,Orders!$A$2:$A$201,0)) -> 202305 | I12: =INDEX(Orders!$E$2:$E$201,MATCH(A12,Orders!$A$2:$A$201,0)) -> Bangalore
A13: 6 | B13: 7 | C13: 2 | D13: 40000 | E13: =C13*D13 -> 80000 | F13: =INDEX(Products!$B$2:$B$9,MATCH(B13,Products!$A$2:$A$9,0)) -> Digital SLR Camera | G13: =INDEX(Products!$C$2:$C$9,MATCH(B13,Products!$A$2:$A$9,0)) -> Photography | H13: =INDEX(Orders!$F$2:$F$201,MATCH(A13,Orders!$A$2:$A$201,0)) -> 202305 | I13: =INDEX(Orders!$E$2:$E$201,MATCH(A13,Orders!$A$2:$A$201,0)) -> Bangalore
... A520: 200 | B520: 6 | C520: 3 | D520: 7000 | E520: =C520*D520 -> 21000 | F520: =INDEX(Products!$B$2:$B$9,MATCH(B520,Products!$A$2:$A$9,0)) -> Portable Bluetooth Speaker | G520: =INDEX(Products!$C$2:$C$9,MATCH(B520,Products!$A$2:$A$9,0)) -> Electronics | H520: =INDEX(Orders!$F$2:$F$201,MATCH(A520,Orders!$A$2:$A$201,0)) -> 202306 | I520: =INDEX(Orders!$E$2:$E$201,MATCH(A520,Orders!$A$2:$A$201,0)) -> Pune

Sheet RFM
A1: customer_id | B1: name | C1: location | D1: recency_days | E1: frequency | F1: monetary | G1: r_score | H1: f_score | I1: m_score | J1: rfm_segment | L1: Source: values from SQL view vw_customer_rfm (sql/03_advanced_sql.sql), scores 1-4 via NTILE(4).
A2: 32 | B2: Romil Bora | C2: Chennai | D2: 92 | E2: 6 | F2: 889000 | G2: 3 | H2: 4 | I2: 4 | J2: Champions
A3: 17 | B3: Rhea Issac | C3: Jaipur | D3: 52 | E3: 4 | F3: 864000 | G3: 4 | H3: 4 | I3: 4 | J3: Champions | L3: Segment | M3: Customers | N3: Revenue | O3: Revenue share
A4: 51 | B4: Indrans Lanka | C4: Lucknow | D4: 0 | E4: 5 | F4: 713000 | G4: 4 | H4: 4 | I4: 4 | J4: Champions | L4: Champions | M4: =COUNTIF($J$2:$J$85,L4) -> 23 | N4: =SUMIF($J$2:$J$85,L4,$F$2:$F$85) -> 10440000 | O4: =N4/SUM($N$4:$N$8) -> 0.52772583
A5: 24 | B5: Samar Sharaf | C5: Mumbai | D5: 36 | E5: 4 | F5: 693000 | G5: 4 | H5: 4 | I5: 4 | J5: Champions | L5: Loyal / Potential | M5: =COUNTIF($J$2:$J$85,L5) -> 12 | N5: =SUMIF($J$2:$J$85,L5,$F$2:$F$85) -> 1441000 | O5: =N5/SUM($N$4:$N$8) -> 0.072840317
A6: 100 | B6: Kimaya Sur | C6: Bangalore | D6: 115 | E6: 3 | F6: 613000 | G6: 3 | H6: 4 | I6: 4 | J6: Champions | L6: Needs Attention | M6: =COUNTIF($J$2:$J$85,L6) -> 20 | N6: =SUMIF($J$2:$J$85,L6,$F$2:$F$85) -> 3421000 | O6: =N6/SUM($N$4:$N$8) -> 0.17292625
A7: 57 | B7: Diya Upadhyay | C7: Kolkata | D7: 74 | E7: 8 | F7: 594000 | G7: 3 | H7: 4 | I7: 4 | J7: Champions | L7: At Risk | M7: =COUNTIF($J$2:$J$85,L7) -> 13 | N7: =SUMIF($J$2:$J$85,L7,$F$2:$F$85) -> 2717000 | O7: =N7/SUM($N$4:$N$8) -> 0.13734014
A8: 84 | B8: Gokul Chhabra | C8: Delhi | D8: 72 | E8: 5 | F8: 592000 | G8: 3 | H8: 4 | I8: 4 | J8: Champions | L8: Lost | M8: =COUNTIF($J$2:$J$85,L8) -> 16 | N8: =SUMIF($J$2:$J$85,L8,$F$2:$F$85) -> 1764000 | O8: =N8/SUM($N$4:$N$8) -> 0.089167467
A9: 78 | B9: Yuvraj Bir | C9: Chennai | D9: 48 | E9: 4 | F9: 562000 | G9: 4 | H9: 4 | I9: 4 | J9: Champions
A10: 41 | B10: Ehsaan Chand | C10: Hyderabad | D10: 34 | E10: 4 | F10: 558000 | G10: 4 | H10: 4 | I10: 4 | J10: Champions
A11: 35 | B11: Miraya Mand | C11: Chennai | D11: 124 | E11: 2 | F11: 463000 | G11: 2 | H11: 2 | I11: 4 | J11: Needs Attention
A12: 95 | B12: Kartik Bhakta | C12: Ahmedabad | D12: 62 | E12: 3 | F12: 463000 | G12: 3 | H12: 4 | I12: 4 | J12: Champions
A13: 59 | B13: Yasmin Mallick | C13: Bangalore | D13: 191 | E13: 2 | F13: 444000 | G13: 1 | H13: 3 | I13: 4 | J13: At Risk
A14: 4 | B14: Charvi Balay | C14: Pune | D14: 57 | E14: 3 | F14: 444000 | G14: 4 | H14: 3 | I14: 4 | J14: Champions
A15: 38 | B15: Saksham Barman | C15: Ahmedabad | D15: 58 | E15: 3 | F15: 427000 | G15: 4 | H15: 3 | I15: 4 | J15: Champions
A16: 61 | B16: Saksham Buch | C16: Kolkata | D16: 69 | E16: 5 | F16: 427000 | G16: 3 | H16: 4 | I16: 4 | J16: Champions
A17: 36 | B17: Ivana Acharya | C17: Lucknow | D17: 150 | E17: 2 | F17: 373000 | G17: 2 | H17: 2 | I17: 4 | J17: Needs Attention
A18: 88 | B18: Sumer Dora | C18: Chennai | D18: 5 | E18: 4 | F18: 336000 | G18: 4 | H18: 4 | I18: 4 | J18: Champions
A19: 19 | B19: Sahil Chaudhary | C19: Pune | D19: 222 | E19: 1 | F19: 321000 | G19: 1 | H19: 1 | I19: 4 | J19: Lost
A20: 85 | B20: Aarna Kurian | C20: Hyderabad | D20: 137 | E20: 3 | F20: 315000 | G20: 2 | H20: 3 | I20: 4 | J20: At Risk
... A85: 70 | B85: Dhruv Rajagopal | C85: Delhi | D85: 330 | E85: 1 | F85: 10000 | G85: 1 | H85: 1 | I85: 1 | J85: Lost
